2024-02-21 21:10:01,114 INFO: Microblog startup [in C:\Users\Isuri\OneDrive\Documents\BluchipProject\FlaskTuturial_task4\Chapter8\app\__init__.py:43]
2024-02-21 21:10:25,823 INFO: Microblog startup [in C:\Users\Isuri\OneDrive\Documents\BluchipProject\FlaskTuturial_task4\Chapter8\app\__init__.py:43]
2024-02-21 21:15:50,184 INFO: Microblog startup [in C:\Users\Isuri\OneDrive\Documents\BluchipProject\FlaskTuturial_task4\Chapter8\app\__init__.py:43]
2024-02-21 21:18:04,516 INFO: Microblog startup [in C:\Users\Isuri\OneDrive\Documents\BluchipProject\FlaskTuturial_task4\Chapter8\app\__init__.py:43]
2024-02-21 23:39:09,809 INFO: Microblog startup [in C:\Users\Isuri\OneDrive\Documents\BluchipProject\FlaskTuturial_task4\Chapter9\app\__init__.py:43]
2024-02-22 10:18:11,362 INFO: Microblog startup [in C:\Users\Isuri\OneDrive\Documents\BluchipProject\FlaskTuturial_task4\Chapter10\app\__init__.py:45]
2024-02-22 10:53:46,581 INFO: Microblog startup [in C:\Users\Isuri\OneDrive\Documents\BluchipProject\FlaskTuturial_task4\Chapter10\app\__init__.py:45]
2024-02-22 10:54:32,692 ERROR: Exception on /register [POST] [in C:\Users\Isuri\AppData\Roaming\Python\Python311\site-packages\flask\app.py:828]
Traceback (most recent call last):
  File "C:\Users\Isuri\AppData\Roaming\Python\Python311\site-packages\wtforms\validators.py", line 401, in __call__
    import email_validator
ModuleNotFoundError: No module named 'email_validator'

The above exception was the direct cause of the following exception:

Traceback (most recent call last):
  File "C:\Users\Isuri\AppData\Roaming\Python\Python311\site-packages\flask\app.py", line 1463, in wsgi_app
    response = self.full_dispatch_request()
               ^^^^^^^^^^^^^^^^^^^^^^^^^^^^
  File "C:\Users\Isuri\AppData\Roaming\Python\Python311\site-packages\flask\app.py", line 872, in full_dispatch_request
    rv = self.handle_user_exception(e)
         ^^^^^^^^^^^^^^^^^^^^^^^^^^^^^
  File "C:\Users\Isuri\AppData\Roaming\Python\Python311\site-packages\flask\app.py", line 870, in full_dispatch_request
    rv = self.dispatch_request()
         ^^^^^^^^^^^^^^^^^^^^^^^
  File "C:\Users\Isuri\AppData\Roaming\Python\Python311\site-packages\flask\app.py", line 855, in dispatch_request
    return self.ensure_sync(self.view_functions[rule.endpoint])(**view_args)  # type: ignore[no-any-return]
           ^^^^^^^^^^^^^^^^^^^^^^^^^^^^^^^^^^^^^^^^^^^^^^^^^^^^^^^^^^^^^^^^^
  File "C:\Users\Isuri\OneDrive\Documents\BluchipProject\FlaskTuturial_task4\Chapter10\app\routes.py", line 88, in register
    if form.validate_on_submit():
       ^^^^^^^^^^^^^^^^^^^^^^^^^
  File "C:\Users\Isuri\AppData\Roaming\Python\Python311\site-packages\flask_wtf\form.py", line 86, in validate_on_submit
    return self.is_submitted() and self.validate(extra_validators=extra_validators)
                                   ^^^^^^^^^^^^^^^^^^^^^^^^^^^^^^^^^^^^^^^^^^^^^^^^
  File "C:\Users\Isuri\AppData\Roaming\Python\Python311\site-packages\wtforms\form.py", line 329, in validate
    return super().validate(extra)
           ^^^^^^^^^^^^^^^^^^^^^^^
  File "C:\Users\Isuri\AppData\Roaming\Python\Python311\site-packages\wtforms\form.py", line 146, in validate
    if not field.validate(self, extra):
           ^^^^^^^^^^^^^^^^^^^^^^^^^^^
  File "C:\Users\Isuri\AppData\Roaming\Python\Python311\site-packages\wtforms\fields\core.py", line 246, in validate
    stop_validation = self._run_validation_chain(form, chain)
                      ^^^^^^^^^^^^^^^^^^^^^^^^^^^^^^^^^^^^^^^
  File "C:\Users\Isuri\AppData\Roaming\Python\Python311\site-packages\wtforms\fields\core.py", line 266, in _run_validation_chain
    validator(form, self)
  File "C:\Users\Isuri\AppData\Roaming\Python\Python311\site-packages\wtforms\validators.py", line 403, in __call__
    raise Exception(
Exception: Install 'email_validator' for email validation support.
2024-02-22 10:55:34,305 ERROR: Exception on /register [POST] [in C:\Users\Isuri\AppData\Roaming\Python\Python311\site-packages\flask\app.py:828]
Traceback (most recent call last):
  File "C:\Users\Isuri\AppData\Roaming\Python\Python311\site-packages\wtforms\validators.py", line 401, in __call__
    import email_validator
ModuleNotFoundError: No module named 'email_validator'

The above exception was the direct cause of the following exception:

Traceback (most recent call last):
  File "C:\Users\Isuri\AppData\Roaming\Python\Python311\site-packages\flask\app.py", line 1463, in wsgi_app
    response = self.full_dispatch_request()
               ^^^^^^^^^^^^^^^^^^^^^^^^^^^^
  File "C:\Users\Isuri\AppData\Roaming\Python\Python311\site-packages\flask\app.py", line 872, in full_dispatch_request
    rv = self.handle_user_exception(e)
         ^^^^^^^^^^^^^^^^^^^^^^^^^^^^^
  File "C:\Users\Isuri\AppData\Roaming\Python\Python311\site-packages\flask\app.py", line 870, in full_dispatch_request
    rv = self.dispatch_request()
         ^^^^^^^^^^^^^^^^^^^^^^^
  File "C:\Users\Isuri\AppData\Roaming\Python\Python311\site-packages\flask\app.py", line 855, in dispatch_request
    return self.ensure_sync(self.view_functions[rule.endpoint])(**view_args)  # type: ignore[no-any-return]
           ^^^^^^^^^^^^^^^^^^^^^^^^^^^^^^^^^^^^^^^^^^^^^^^^^^^^^^^^^^^^^^^^^
  File "C:\Users\Isuri\OneDrive\Documents\BluchipProject\FlaskTuturial_task4\Chapter10\app\routes.py", line 88, in register
    if form.validate_on_submit():
       ^^^^^^^^^^^^^^^^^^^^^^^^^
  File "C:\Users\Isuri\AppData\Roaming\Python\Python311\site-packages\flask_wtf\form.py", line 86, in validate_on_submit
    return self.is_submitted() and self.validate(extra_validators=extra_validators)
                                   ^^^^^^^^^^^^^^^^^^^^^^^^^^^^^^^^^^^^^^^^^^^^^^^^
  File "C:\Users\Isuri\AppData\Roaming\Python\Python311\site-packages\wtforms\form.py", line 329, in validate
    return super().validate(extra)
           ^^^^^^^^^^^^^^^^^^^^^^^
  File "C:\Users\Isuri\AppData\Roaming\Python\Python311\site-packages\wtforms\form.py", line 146, in validate
    if not field.validate(self, extra):
           ^^^^^^^^^^^^^^^^^^^^^^^^^^^
  File "C:\Users\Isuri\AppData\Roaming\Python\Python311\site-packages\wtforms\fields\core.py", line 246, in validate
    stop_validation = self._run_validation_chain(form, chain)
                      ^^^^^^^^^^^^^^^^^^^^^^^^^^^^^^^^^^^^^^^
  File "C:\Users\Isuri\AppData\Roaming\Python\Python311\site-packages\wtforms\fields\core.py", line 266, in _run_validation_chain
    validator(form, self)
  File "C:\Users\Isuri\AppData\Roaming\Python\Python311\site-packages\wtforms\validators.py", line 403, in __call__
    raise Exception(
Exception: Install 'email_validator' for email validation support.
2024-02-22 10:57:29,418 INFO: Microblog startup [in C:\Users\Isuri\OneDrive\Documents\BluchipProject\FlaskTuturial_task4\Chapter10\app\__init__.py:45]
